Workbook

Sheet FS Balance Sheet 2026
A4: Balance Sheet
A5: 46265
A6: Assets
B8: Current Assets
C9: Cash and Cash Equivalents | E9: =SUM('August 2026 - Balance Sheet'!E11:E11) -> 10056039
C10: Contract Receivables | E10: =SUM('August 2026 - Balance Sheet'!E12)-'August 2026 -AR Aging'!F441 -> 22228480
C11: Other Receivables | E11: =SUM('August 2026 - Balance Sheet'!E13) -> 337927.71
C12: Prepaid Expenses and Other Current Assets | E12: =SUM('August 2026 - Balance Sheet'!E41:E45,'August 2026 - Balance Sheet'!E15) -> 765744.18
C13: Contract Assets* | E13: =SUM('August 2026 - Balance Sheet'!E14+'August 2026 - Over Under Report'!P85+'August 2026 -AR Aging'!F441) -> -4021061.7
C16: Total Current Assets: | E16: =SUM(E9:E15) -> 29367129
B18: Property and Equipment
C20: Vehicles | E20: =SUM('August 2026 - Balance Sheet'!E21) -> 100000
C21: Office Equipment | E21: =SUM('August 2026 - Balance Sheet'!E22) -> 3772.74
C22: Furniture and Fixtures | E22: =SUM('August 2026 - Balance Sheet'!E24) -> 62228.65
C23: Less Accumulated Depreciation | E23: =SUM('August 2026 - Balance Sheet'!E30,'August 2026 - Balance Sheet'!E31,'August 2026 - Balance Sheet'!E33) -> -45959.8
C25: Total Property and Equipment | E25: =SUM(E20:E24) -> 120041.59
B27: Other Assets
C28: Software Costs, net of Accumulated Amortization | E28: =SUM('August 2026 - Balance Sheet'!E23,'August 2026 - Balance Sheet'!E32) -> 36000
D31: Total Assets: | E31: =SUM(E16,E25,E28) -> 29523170
A33: Liabilities
B35: Current Liabilities
C37: Accounts Payable | E37: =SUM('August 2026 - Balance Sheet'!E56) -> 3871881.6
C38: Accrued Liabilities | E38: =SUM('August 2026 - Balance Sheet'!E59:E67) -> 11423882
C39: Notes Payable | E39: =SUM('August 2026 - Balance Sheet'!E68) -> 0
C40: Distributions Payable | E40: ='August 2026 - Balance Sheet'!E58 -> 164495.96
C41: Contract Liabilities* | E41: =SUM('August 2026 - Balance Sheet'!E57+'August 2026 - Over Under Report'!P85) -> -7188881.2
C44: Total Current Liabilities | E44: =SUM(E37:E43) -> 8271378.5
B46: Notes Payable to Stockholders | E46: =SUM('August 2026 - Balance Sheet'!E74:E77) -> 1044085
C48: Total Liabilities | E48: =SUM(E44,E46) -> 9315463.5
B50: Stockholder's Equity
C51: Common Stock | E51: =SUM('August 2026 - Balance Sheet'!E87:E91) -> 1000
C52: Additional Paid-in Capital | E52: =SUM('August 2026 - Balance Sheet'!E92) -> 0
C53: Retained Earnings | E53: =SUM('August 2026 - Balance Sheet'!E93,'August 2026 - Balance Sheet'!E99)+'August 2026 - Inc. Stmt- ALL'!G130 -> 20206707
C54: Total Stockholder's Equity | E54: =SUM(E51:E53) -> 20207707
D56: Total Liabilities and Equity: | E56: =SUM(E48,E54) -> 29523170
E60: =E56-E31 -> 0

Sheet FS Stmt of Inc & RE- 2026
A7: Statement of Income and Retained Earnings
A8: January 1, 2026 - August 31, 2026
C10: 2026 | D10: 2019 | E10: 2018 | F10: 2017 | G10: 2016
A12: Contract Revenues | C12: =SUM('August 2026 - Inc. Stmt- ALL'!G17:G18) -> 64039629 | D12: 43843514 | E12: 50727670 | F12: 33398814 | G12: 19662807
A14: Costs of Contract Revenues | C14: =SUM('August 2026 - Inc. Stmt- ALL'!G35) -> 52485705 | D14: 40056194 | E14: 43612053 | F14: 29104212 | G14: 15862450
A16: Gross Profit | C16: =SUM(C12-C14) -> 11553924 | D16: 3787320.2 | E16: 7115616.9 | F16: 4294601.8 | G16: 3800357.5
A18: Operating Expenses | C18: ='August 2026 - Inc. Stmt- ALL'!G96+'August 2026 - Inc. Stmt- ALL'!G86-'August 2026 - Inc. Stmt- ALL'!G71+'August 2026 - Inc. Stmt- ALL'!G125+'August 2026 - Inc. Stmt- ALL'!G128 -> 2041561.7 | D18: 1497446 | E18: 1549793.3 | F18: 2457828.2 | G18: 2242522.8
A20: Income before Other Income (Expense) | C20: =SUM(C16-C18) -> 9512362.5 | D20: 2289874.2 | E20: 5565823.6 | F20: 1836773.7 | G20: 1557834.8
A22: Other Income (Expense)
B23: Interest Income | C23: =SUM('August 2026 - Inc. Stmt- ALL'!G113) -> 89971.27 | D23: 0 | E23: 0 | F23: 0 | G23: 0
B24: Miscellaneous Income | C24: ='August 2026 - Inc. Stmt- ALL'!G19+'August 2026 - Inc. Stmt- ALL'!G110+'August 2026 - Inc. Stmt- ALL'!G111+'August 2026 - Inc. Stmt- ALL'!G112+'August 2026 - Inc. Stmt- ALL'!G114 -> 188235.87 | D24: 619186.78 | E24: 40284.15 | F24: 29891.49 | G24: 53610.93
B25: Interest Expense | C25: =SUM('August 2026 - Inc. Stmt- ALL'!G71)*-1 -> -44085.42 | D25: -121829.35 | E25: -121542.34 | F25: -76540.68 | G25: -76540.68
B27: Total Other Income (Expense) | C27: =SUM(C23:C25) -> 234121.72 | D27: 497357.43 | E27: -81258.19 | F27: -46649.19 | G27: -22929.75
B29: Net Income Before Tax: | C29: =+#REF!+C27-#REF!-#REF!-#REF! -> #REF! | D29: #REF! | E29: #REF! | F29: #REF! | G29: #REF!
B31: Net Income: | C31: =SUM(C20,C27) -> 9746484.2 | D31: 2787231.7 | E31: 5484565.4 | F31: 1790124.5 | G31: 1534905
B33: Retained Earnings at Beginning of Year | C33: =SUM('August 2026 - Balance Sheet'!E93) -> 11273709 | D33: 3711295.3 | E33: 1896859.7 | F33: 2676967.5 | G33: 1776331.2
B35: Less Distributions | C35: =-'August 2026 - Balance Sheet'!E101 -> 813486.15 | D35: 893096.63 | E35: 3670129.9 | F35: 782904.11 | G35: 634268.75
B38: Retained Earnings at End of Year (Period) | C38: =SUM(C31,C33)-C35 -> 20206707 | D38: 5605430.3 | E38: 3711295.3 | F38: 3684187.8 | G38: 2676967.5
F40: =SUM(F38-E33) -> 1787328.1
F41: D.Stowell Stock Redemption 1.1.18

Sheet August 2026 - Balance Sheet
A4: Balance Sheet
A5: 46265
A7: Assets
A9: Current Assets
B11: Truist Checking/JP Morgan Money Market | E11: 10056039
B12: Contract Receivables | E12: 22228480 | K12: 11501
B13: Other Receivables | E13: 337927.71
B14: Underbillings | E14: 3167819.5
B15: Payroll Advances | E15: 0
C17: Total Current Assets: | F17: =+SUM(E11:E15) -> 35790266
A19: Long Term Assets
B21: Vehicles | E21: 100000
B22: Office Equipment | E22: 3772.74
B23: Software | E23: 54000
B24: Furniture and Fixtures | E24: 62228.65
C26: Total Long Term Assets: | E26: =+SUM(E21:E24) -> 220001.39
A28: Accumulated Depreciation
B30: Accum Dep'n Vehicles | E30: -33333.4
B31: Accum Dep'n Office Equipment | E31: -3772.74
B32: Accum Amort Software | E32: -18000
B33: Accum Dep'n Furniture & Fxt | E33: -8853.66
C35: Total Accumulated Depreciation: | E35: =+SUM(E30:E33) -> -63959.8
C37: Net Long Term Assets: | F37: =+E26-ABS(E35) -> 156041.59
A39: Other Assets
B41: Prepaid Insurance - 2019 | E41: 58572.08
B42: Prepaid Ins.- Sub. Acct. 2013 | E42: 106789.47
B43: Life Insurance - Employee | E43: 571107.25
B44: Term Life Ins. - Employee | E44: 1071
B45: Prepaid Expenses | E45: 28204.38
C47: Total Other Assets: | F47: =+SUM(E41:E45) -> 765744.18
D49: Total Assets: | F49: =+(+F17+F47+E26)-ABS(E35) -> 36712052
A52: Liabilities
A54: Current Liabilities
B56: Trade Accounts Payable | E56: 3871881.6
B57: Other Accounts Payable
B58: Distributions Payable - SH | E58: 164495.96
B59: Overbillings | E59: 11194804
B60: Fica/FIT Payable | E60: 0
B61: Sales Taxes Payable | E61: 5407.56
B62: TX SUI Payable | E62: 0
...

Sheet August 2026 - Inc. Stmt- ALL
A7: Income Statement - All Departments
A8: 46265
N10: 45900
E11: Over/Under | F11: Over/Under | I11: Over/Under | J11: Over/Under | N11: Prior Year
C12: Period | D12: Budget | E12: Budget % - Period | F12: Budget - Period | G12: YTD | H12: Budget | I12: Budget % - YTD | J12: Budget - YTD | K12: 2026 BUDGET | N12: YTD | O12: Var
S13: YTD Months | T13: 8
A15: Operating Income
B17: Contract Income | C17: 8306017.2 | D17: =SUM(K17/12) -> 6666666.7 | F17: =SUM(C17-D17) -> 1639350.6 | G17: 61018486 | H17: =SUM(D17*T$13) -> 53333333 | J17: =SUM(G17-H17) -> 7685152.6 | K17: =K21 -> 80000000
B18: Over/Underbillings | C18: -338708.68 | D18: 0 | G18: 3021143.1 | H18: =SUM(D18*T$13) -> 0
B19: Discounts Earned | C19: 22205.49 | D19: 0 | G19: 193081.97 | H19: =SUM(D19*T$13) -> 0
B21: Total Operating Income: | C21: =SUM(C17:C20) -> 7989514.1 | D21: =SUM(D17:D20) -> 6666666.7 | E21: =((C21-D21)/D21)*100 -> 19.842711 | F21: =SUM(C21-D21) -> 1322847.4 | G21: =SUM(G17:G20) -> 64232711 | H21: =SUM(H17:H20) -> 53333333 | I21: =((G21-H21)/H21)*100 -> 20.436333 | J21: =SUM(G21-H21) -> 10899378 | K21: 80000000 | N21: 48256343 | O21: =G21-N21 -> 15976368
A23: Direct Expense
B25: Material | C25: 1351245.8 | D25: 0 | G25: 15541061 | H25: =SUM(D25*T$13) -> 0
B26: Equipment Expense | C26: 173046.29 | D26: 0 | G26: 2670010.6 | H26: =SUM(D26*T$13) -> 0
B27: Subcontracted | C27: 3306313.5 | D27: 0 | G27: 26829372 | H27: =SUM(D27*T$13) -> 0
B28: Other Job Expense | C28: 232181.83 | D28: 0 | G28: 2623558.7 | H28: =SUM(D28*T$13) -> 0
B29: Direct Labor | C29: 562355.92 | D29: 0 | G29: 4350728 | H29: =SUM(D29*T$13) -> 0
B30: D/L Payroll Taxes | C30: 36959.76 | D30: 0 | G30: 302849.51 | H30: =SUM(D30*T$13) -> 0
B31: D/L Workers' Compensation | C31: 4146.39 | D31: 0 | G31: 30050.81 | H31: =SUM(D31*T$13) -> 0
B32: D/L Benefits | C32: 0 | D32: 0 | G32: 138074.05 | H32: =SUM(D32*T$13) -> 0
B35: Total Direct Expense: | C35: =SUM(C25:C34) -> 5666249.5 | D35: =SUM(D17*0.8468) -> 5645333.3 | E35: =((C35-D35)/D35) -> 0.0037050366 | F35: =SUM(C35-D35) -> 20916.167 | G35: =SUM(G25:G34) -> 52485705 | H35: =K35/12*T13 -> 45164445 | I35: =((G35-H35)/H35) -> 0.1621023 | J35: =H35-G35 -> -7321260.2 | K35: 67746667 | N35: 41029273 | O35: =N35-G35 -> -11456432
B38: Total Direct & Equip/Shop Expense: | C38: =SUM(C35) -> 5666249.5 | D38: 0 | G38: =SUM(G35) -> 52485705 | H38: =H35 -> 45164445 | K38: =K35 -> 67746667
B40: Gross Profit: | C40: =+C21-C35 -> 2323264.6 | D40: =+D21-D35 -> 1021333.3 | G40: =+G21-G35 -> 11747006 | H40: =+H21-H35 -> 8168888.7 | J40: =G40-H40 -> 3578117.5 | K40: =+K21-K35 -> 12253333 | N40: =N21-N35 -> 7227069.7 | O40: =G40-N40 -> 4519936.5
B42: % Operating Income: | C42: =SUM(C40/C21)*100% -> 0.29078922 | D42: =SUM(D40/D21)*100% -> 0.1532 | G42: =SUM(G40/G21)*100% -> 0.18288199 | H42: =SUM(H40/H21)*100% -> 0.15316666 | K42: =SUM(K40/K21)*100% -> 0.15316666 | N42: =N40/N21 -> 0.14976414
A44: Overhead Expense
B46: Rent | C46: 17342.58 | D46: =SUM(K46/12) -> 20143.39 | F46: =SUM(C46-D46) -> -2800.81 | G46: 154110.28 | H46: =SUM(D46*T$13) -> 161147.12 | J46: =H46-G46 -> 7036.84 | K46: 241720.68
B47: Office Supplies | C47: 0 | D47: =SUM(K47/12) -> 1500 | F47: =SUM(C47-D47) -> -1500 | G47: -114.16 | H47: =SUM(D47*T$13) -> 12000 | J47: =H47-G47 -> 12114.16 | K47: 18000
B48: Office Expense | C48: 143531.77 | D48: =SUM(K48/12) -> 6250 | F48: =SUM(C48-D48) -> 137281.77 | G48: 237962.9 | H48: =SUM(D48*T$13) -> 50000 | J48: =H48-G48 -> -187962.9 | K48: 75000
B49: Utilities | C49: 433.32 | D49: =SUM(K49/12) -> 1033.8333 | F49: =SUM(C49-D49) -> -600.51333 | G49: 6329.86 | H49: =SUM(D49*T$13) -> 8270.6667 | J49: =H49-G49 -> 1940.8067 | K49: 12406
B50: Telephone | C50: 343.38 | D50: =SUM(K50/12) -> 489.16667 | F50: =SUM(C50-D50) -> -145.78667 | G50: 2901.3 | H50: =SUM(D50*T$13) -> 3913.3333 | J50: =H50-G50 -> 1012.0333 | K50: 5870
B51: Cellular Phone | C51: 1805.88 | D51: =SUM(K51/12) -> 2566.6667 | F51: =SUM(C51-D51) -> -760.78667 | G51: 18165.71 | H51: =SUM(D51*T$13) -> 20533.333 | J51: =H51-G51 -> 2367.6233 | K51: 30800
B52: IT Services | C52: 2435 | D52: =SUM(K52/12) -> 2941.6667 | F52: =SUM(C52-D52) -> -506.66667 | G52: 108020 | H52: =SUM(D52*T$13) -> 23533.333 | J52: =H52-G52 -> -84486.667 | K52: 35300
B53: Internet Service | C53: 1334.06 | D53: =SUM(K53/12) -> 1295 | F53: =SUM(C53-D53) -> 39.06 | G53: 10501.5 | H53: =SUM(D53*T$13) -> 10360 | J53: =H53-G53 -> -141.5 | K53: 15540
B54: Bank Charges | C54: 329.13 | D54: =SUM(K54/12) -> 1131.4167 | F54: =SUM(C54-D54) -> -802.28667 | G54: 1049.32 | H54: =SUM(D54*T$13) -> 9051.3333 | J54: =H54-G54 -> 8002.0133 | K54: 13577
B55: Postage and Freight | C55: 753.94 | D55: =SUM(K55/12) -> 572.75 | F55: =SUM(C55-D55) -> 181.19 | G55: 3107.39 | H55: =SUM(D55*T$13) -> 4582 | J55: =H55-G55 -> 1474.61 | K55: 6873
B56: Janitorial | C56: 470 | D56: =SUM(K56/12) -> 541.66667 | F56: =SUM(C56-D56) -> -71.666667 | G56: 4170 | H56: =SUM(D56*T$13) -> 4333.3333 | J56: =H56-G56 -> 163.33333 | K56: 6500
B57: Advertising and Promotion | C57: 0 | D57: =SUM(K57/12) -> 17.416667 | F57: =SUM(C57-D57) -> -17.416667 | G57: 12126.35 | H57: =SUM(D57*T$13) -> 139.33333 | J57: =H57-G57 -> -11987.017 | K57: 209
... B68: Charity Donations | C68: 0 | D68: =SUM(K68/12) -> 1058 | F68: =SUM(C68-D68) -> -1058 | G68: 6645.08 | H68: =SUM(D68*T$13) -> 8464 | J68: =H68-G68 -> 1818.92 | K68: 12696
B69: General Insurance /Life | C69: 0 | D69: =SUM(K69/12) -> 5602 | F69: =SUM(C69-D69) -> -5602 | G69: 18566.33 | H69: =SUM(D69*T$13) -> 44816 | J69: =H69-G69 -> 26249.67 | K69: =43192+24032 -> 67224
B70: Taxes and Licenses | C70: 0 | D70: =SUM(K70/12) -> 24.833333 | F70: =SUM(C70-D70) -> -24.833333 | G70: 453.4 | H70: =SUM(D70*T$13) -> 198.66667 | J70: =H70-G70 -> -254.73333 | K70: 298
...

Sheet August 2026 - Over Under Report
A6: Over/Under Billings - August 31, 2026 | P6: NEW CONTRACT ASSET/LIABILITY ENTRY
P7: ADJUSTMENT TO NET | Y7: 23022 | Z7: 19646.46 | AA7: Dr
P8: CONTRACT ASSET AND | Q8: Retainage from
A9: Job# | C9: Costs | D9: / | E9: Budget | F9: = % | G9: X | H9: Contract | I9: = | J9: Earned | K9: - | L9: Billed | M9: = | N9: Over/Under | P9: CONTRACT LIABILITY | Q9: AR Aging | Y9: 14220
A11: 10120 - 10120 - Waller Creek | C11: 13012238 | E11: 13081470 | F11: =+IF(E11>0,ROUND((100*C11)/E11,2),0) -> 99.47 | H11: 15374369 | J11: =+IF(E11>0,ROUND(H11*F11/100,2),0) -> 15292885 | L11: 15374369 | N11: =+IF(E11>0,J11-L11,0) -> -81484.16 | P11: =IF(N11<0,IF(-N11<Q11,N11,-Q11),0) -> -81484.16 | Q11: ='August 2026 -AR Aging'!G32 -> 1537436.9
A12: 10123 - 10123 - 400 Central* | C12: 23071770 | E12: 23071770 | F12: =+IF(E12>0,ROUND((100*C12)/E12,2),0) -> 100 | H12: 26422594 | J12: =+IF(E12>0,ROUND(H12*F12/100,2),0) -> 26422594 | L12: 26382590 | N12: =+IF(E12>0,J12-L12,0) -> 40003.2 | P12: =IF(N12<0,IF(-N12<Q12,N12,-Q12),0) -> 0 | Q12: ='August 2026 -AR Aging'!G38 -> 0
A13: 10128 - 1000 First Avenue Apartments | C13: 7238034.2 | E13: 7238034.2 | F13: =+IF(E13>0,ROUND((100*C13)/E13,2),0) -> 100 | H13: 9863898.7 | J13: =+IF(E13>0,ROUND(H13*F13/100,2),0) -> 9863898.7 | L13: 9868777.9 | N13: =+IF(E13>0,J13-L13,0) -> -4879.22 | P13: =IF(N13<0,IF(-N13<Q13,N13,-Q13),0) -> -4879.22 | Q13: ='August 2026 -AR Aging'!G53 -> 47413.81
A14: 10130 - 10130 - Art House Condominiums | C14: 11018134 | E14: 11017873 | F14: =+IF(E14>0,ROUND((100*C14)/E14,2),0) -> 100 | H14: 15546324 | J14: =+IF(E14>0,ROUND(H14*F14/100,2),0) -> 15546324 | L14: 15547951 | N14: =+IF(E14>0,J14-L14,0) -> -1627.43 | P14: =IF(N14<0,IF(-N14<Q14,N14,-Q14),0) -> -1627.43 | Q14: ='August 2026 -AR Aging'!G59 -> 1627.43
A15: 10132 - 10132 - Fairfield Ave | C15: 262643.09 | E15: 5076190.6 | F15: =+IF(E15>0,ROUND((100*C15)/E15,2),0) -> 5.17 | H15: 6295775.3 | J15: =+IF(E15>0,ROUND(H15*F15/100,2),0) -> 325491.58 | N15: =+IF(E15>0,J15-L15,0) -> 325491.58 | P15: =IF(N15<0,IF(-N15<Q15,N15,-Q15),0) -> 0
A16: 10135 - 10135 - 3rd & 3rd | C16: 4932904.3 | E16: 6188300 | F16: =+IF(E16>0,ROUND((100*C16)/E16,2),0) -> 79.71 | H16: 7318353.5 | J16: =+IF(E16>0,ROUND(H16*F16/100,2),0) -> 5833459.6 | L16: 7074613.5 | N16: =+IF(E16>0,J16-L16,0) -> -1241153.9 | P16: =IF(N16<0,IF(-N16<Q16,N16,-Q16),0) -> -707461.34 | Q16: ='August 2026 -AR Aging'!G80 -> 707461.34
A17: 10141 - 10141 Encore | C17: 11729121 | E17: 12455595 | F17: =+IF(E17>0,ROUND((100*C17)/E17,2),0) -> 94.17 | H17: 15234099 | J17: =+IF(E17>0,ROUND(H17*F17/100,2),0) -> 14345951 | L17: 15207629 | N17: =+IF(E17>0,J17-L17,0) -> -861677.91 | P17: =IF(N17<0,IF(-N17<Q17,N17,-Q17),0) -> 0 | Q17: ='August 2026 -AR Aging'!G101 -> 0
A18: 10142 - 10142 - Jacksonville Shipyards | C18: 24255357 | E18: 37509647 | F18: =+IF(E18>0,ROUND((100*C18)/E18,2),0) -> 64.66 | H18: 42437799 | J18: =+IF(E18>0,ROUND(H18*F18/100,2),0) -> 27440281 | L18: 30946661 | N18: =+IF(E18>0,J18-L18,0) -> -3506380.3 | P18: =IF(N18<0,IF(-N18<Q18,N18,-Q18),0) -> -3094666.1 | Q18: ='August 2026 -AR Aging'!G128 -> 3094666.1
A19: 10143 - 10143 MetWest | C19: 7955785.9 | E19: 7944692 | F19: =+IF(E19>0,ROUND((100*C19)/E19,2),0) -> 100.14 | H19: 9738808.3 | J19: =+IF(E19>0,ROUND(H19*F19/100,2),0) -> 9752442.7 | L19: 9646072.3 | N19: =+IF(E19>0,J19-L19,0) -> 106370.37 | P19: =IF(N19<0,IF(-N19<Q19,N19,-Q19),0) -> 0 | Q19: ='August 2026 -AR Aging'!G143 -> 0
A20: 10147 - 10147 Jordan House | C20: 446832.4 | E20: 452457 | F20: =+IF(E20>0,ROUND((100*C20)/E20,2),0) -> 98.76 | H20: 700547 | J20: =+IF(E20>0,ROUND(H20*F20/100,2),0) -> 691860.22 | L20: 700547 | N20: =+IF(E20>0,J20-L20,0) -> -8686.78 | P20: =IF(N20<0,IF(-N20<Q20,N20,-Q20),0) -> 0 | Q20: ='August 2026 -AR Aging'!G149 -> 0
A21: 10148 - 10148-Hilton Repairs Conrad* | C21: 42599.72 | E21: 42599.72 | F21: =+IF(E21>0,ROUND((100*C21)/E21,2),0) -> 100 | H21: 26175 | J21: =+IF(E21>0,ROUND(H21*F21/100,2),0) -> 26175 | L21: 29160 | N21: =+IF(E21>0,J21-L21,0) -> -2985 | P21: =IF(N21<0,IF(-N21<Q21,N21,-Q21),0) -> 0
A22: 10152 - 10152 - Westin Cocoa Beach* | C22: 13140128 | E22: 18458300 | F22: =+IF(E22>0,ROUND((100*C22)/E22,2),0) -> 71.19 | H22: 20377781 | J22: =+IF(E22>0,ROUND(H22*F22/100,2),0) -> 14506942 | L22: 16052244 | N22: =+IF(E22>0,J22-L22,0) -> -1545301.8 | P22: =IF(N22<0,IF(-N22<Q22,N22,-Q22),0) -> -1545301.8 | Q22: ='August 2026 -AR Aging'!G171 -> 1607288.3
A23: 10156 - 10156 - Encore NTMC | C23: 458152.23 | E23: 464616.02 | F23: =+IF(E23>0,ROUND((100*C23)/E23,2),0) -> 98.61 | H23: 548180.28 | J23: =+IF(E23>0,ROUND(H23*F23/100,2),0) -> 540560.57 | L23: 548180.29 | N23: =+IF(E23>0,J23-L23,0) -> -7619.72 | P23: =IF(N23<0,IF(-N23<Q23,N23,-Q23),0) -> -7619.72 | Q23: ='August 2026 -AR Aging'!G188 -> 54818.03
A24: 10158 - 10158 - Stephens Residence | C24: 72050.4 | E24: 420800 | F24: =+IF(E24>0,ROUND((100*C24)/E24,2),0) -> 17.12 | H24: 526000 | J24: =+IF(E24>0,ROUND(H24*F24/100,2),0) -> 90051.2 | L24: 261000 | N24: =+IF(E24>0,J24-L24,0) -> -170948.8 | P24: =IF(N24<0,IF(-N24<Q24,N24,-Q24),0) -> -13050 | Q24: ='August 2026 -AR Aging'!G194 -> 13050
A25: 10159 - 10159- Roberts Residence | C25: 542572.99 | E25: 540556.99 | F25: =+IF(E25>0,ROUND((100*C25)/E25,2),0) -> 100.37 | H25: 587000 | J25: =+IF(E25>0,ROUND(H25*F25/100,2),0) -> 589171.9 | L25: 587000 | N25: =+IF(E25>0,J25-L25,0) -> 2171.9 | P25: =IF(N25<0,IF(-N25<Q25,N25,-Q25),0) -> 0
A26: 10162 - 10162-Edition Hotel | C26: 143961.65 | E26: 152395 | F26: =+IF(E26>0,ROUND((100*C26)/E26,2),0) -> 94.47 | H26: 90494 | J26: =+IF(E26>0,ROUND(H26*F26/100,2),0) -> 85489.68 | L26: 90494 | N26: =+IF(E26>0,J26-L26,0) -> -5004.32
A27: 10163 - Building C Retail Center | C27: 606053.58 | E27: 804600 | F27: =+IF(E27>0,ROUND((100*C27)/E27,2),0) -> 75.32 | H27: 1064299 | J27: =+IF(E27>0,ROUND(H27*F27/100,2),0) -> 801630.01 | L27: 1060299 | N27: =+IF(E27>0,J27-L27,0) -> -258668.99 | P27: =IF(N27<0,IF(-N27<Q27,N27,-Q27),0) -> -106029.9 | Q27: ='August 2026 -AR Aging'!G204 -> 106029.9
A28: 10164 - SMC Tampa Reno | C28: 6507.94 | E28: 20600 | F28: =+IF(E28>0,ROUND((100*C28)/E28,2),0) -> 31.59 | H28: 9473.76 | J28: =+IF(E28>0,ROUND(H28*F28/100,2),0) -> 2992.76 | L28: 9473.76 | N28: -1576.26
A29: 10165 - Ravaudage Parking #1 | C29: 3175.71 | E29: 5520 | F29: =+IF(E29>0,ROUND((100*C29)/E29,2),0) -> 57.53 | H29: 8275 | J29: =+IF(E29>0,ROUND(H29*F29/100,2),0) -> 4760.61 | L29: 8275 | N29: =+IF(E29>0,J29-L29,0) -> -3514.39 | P29: =IF(N29<0,IF(-N29<Q29,N29,-Q29),0) -> 0
A30: 10166 - Stratfford Artisan Lakes | E30: 10000 | F30: =+IF(E30>0,ROUND((100*C30)/E30,2),0) -> 0 | H30: 14687.87 | J30: =+IF(E30>0,ROUND(H30*F30/100,2),0) -> 0 | L30: 14687.87 | N30: =+IF(E30>0,J30-L30,0) -> -14687.87 | P30: =IF(N30<0,IF(-N30<Q30,N30,-Q30),0) -> 0
A31: 10167 - 10167 - Ritz Residences North Tower | C31: 6798524.5 | E31: 12512221 | F31: =+IF(E31>0,ROUND((100*C31)/E31,2),0) -> 54.34 | H31: 14604901 | J31: =+IF(E31>0,ROUND(H31*F31/100,2),0) -> 7936303.3 | L31: 10178644 | N31: =+IF(E31>0,J31-L31,0) -> -2242340.9 | P31: =IF(N31<0,IF(-N31<Q31,N31,-Q31),0) -> -1018289.3 | Q31: ='August 2026 -AR Aging'!G224 -> 1018289.3
A32: 10170 - 10170 - Miami Freedom Park | C32: 30782.3 | E32: 56300 | F32: =+IF(E32>0,ROUND((100*C32)/E32,2),0) -> 54.68 | H32: 77405 | J32: =+IF(E32>0,ROUND(H32*F32/100,2),0) -> 42325.05 | L32: 77405 | N32: =+IF(E32>0,J32-L32,0) -> -35079.95 | P32: =IF(N32<0,IF(-N32<Q32,N32,-Q32),0) -> 0 | Q32: ='August 2026 -AR Aging'!G230 -> 0
A33: 10171 - 10171 - Boulanger Drywall* | C33: 154636.83 | E33: 154636.83 | F33: =+IF(E33>0,ROUND((100*C33)/E33,2),0) -> 100 | H33: 0 | J33: =+IF(E33>0,ROUND(H33*F33/100,2),0) -> 0 | L33: 209987.44 | N33: -209987.44
A34: 10173 - 10173 - Retail Center B | C34: 200354.46 | E34: 489781 | F34: =+IF(E34>0,ROUND((100*C34)/E34,2),0) -> 40.91 | H34: 633270 | J34: =+IF(E34>0,ROUND(H34*F34/100,2),0) -> 259070.76 | L34: 592020 | N34: =+IF(E34>0,J34-L34,0) -> -332949.24 | P34: =IF(N34<0,IF(-N34<Q34,N34,-Q34),0) -> -59202 | Q34: ='August 2026 -AR Aging'!G239 -> 59202
A35: 10174 - 10174 - Retail Center D | C35: 762924.71 | E35: 1019540 | F35: =+IF(E35>0,ROUND((100*C35)/E35,2),0) -> 74.83 | H35: 1269617 | J35: =+IF(E35>0,ROUND(H35*F35/100,2),0) -> 950054.4 | L35: 1264617 | N35: =+IF(E35>0,J35-L35,0) -> -314562.6 | P35: =IF(N35<0,IF(-N35<Q35,N35,-Q35),0) -> -126461.7 | Q35: ='August 2026 -AR Aging'!G250 -> 126461.7
A36: 10175 - 10175 -Totum Market | C36: 193714.22 | E36: 200000 | F36: =+IF(E36>0,ROUND((100*C36)/E36,2),0) -> 96.86 | H36: 230000 | J36: =+IF(E36>0,ROUND(H36*F36/100,2),0) -> 222778 | L36: 230000 | N36: =+IF(E36>0,J36-L36,0) -> -7222 | P36: =IF(N36<0,IF(-N36<Q36,N36,-Q36),0) -> -7222 | Q36: ='August 2026 -AR Aging'!G262 -> 23000
A37: 10176 - 10176 -The Avery* | C37: 238084.35 | E37: 819967 | F37: =+IF(E37>0,ROUND((100*C37)/E37,2),0) -> 29.04 | H37: 967213.66 | J37: =+IF(E37>0,ROUND(H37*F37/100,2),0) -> 280878.85 | L37: 88375 | N37: =+IF(E37>0,J37-L37,0) -> 192503.85 | P37: =IF(N37<0,IF(-N37<Q37,N37,-Q37),0) -> 0 | Q37: ='August 2026 -AR Aging'!G268 -> 8837.5
A38: 10178 - 10178 - Retail A* | C38: 523996.16 | E38: 1074230 | F38: =+IF(E38>0,ROUND((100*C38)/E38,2),0) -> 48.78 | H38: 1350435 | J38: =+IF(E38>0,ROUND(H38*F38/100,2),0) -> 658742.19 | L38: 1338800 | N38: =+IF(E38>0,J38-L38,0) -> -680057.81 | P38: =IF(N38<0,IF(-N38<Q38,N38,-Q38),0) -> -133880 | Q38: ='August 2026 -AR Aging'!G276 -> 133880
A39: 10179 - 10179 - Retail E | C39: 332369.79 | E39: 993530 | F39: =+IF(E39>0,ROUND((100*C39)/E39,2),0) -> 33.45 | H39: 1329537 | J39: =+IF(E39>0,ROUND(H39*F39/100,2),0) -> 444730.13 | L39: 1236800 | N39: =+IF(E39>0,J39-L39,0) -> -792069.87 | P39: =IF(N39<0,IF(-N39<Q39,N39,-Q39),0) -> -123680 | Q39: ='August 2026 -AR Aging'!G284 -> 123680
A40: 10180 - 10180 - Retail F* | C40: 72644.86 | E40: 396560 | F40: =+IF(E40>0,ROUND((100*C40)/E40,2),0) -> 18.32 | H40: 495700 | J40: =+IF(E40>0,ROUND(H40*F40/100,2),0) -> 90812.24 | L40: 491700 | N40: =+IF(E40>0,J40-L40,0) -> -400887.76 | P40: =IF(N40<0,IF(-N40<Q40,N40,-Q40),0) -> -49170 | Q40: ='August 2026 -AR Aging'!G291 -> 49170
A41: 10181 - 10181 - PCL Civil Office | C41: 275575.92 | E41: 275576 | F41: =+IF(E41>0,ROUND((100*C41)/E41,2),0) -> 100 | H41: 350131.35 | J41: =+IF(E41>0,ROUND(H41*F41/100,2),0) -> 350131.35 | L41: 350131.35 | N41: =+IF(E41>0,J41-L41,0) -> 0 | P41: =IF(N41<0,IF(-N41<Q41,N41,-Q41),0) -> 0 | Q41: ='August 2026 -AR Aging'!G303 -> 0
A42: 10182 - Disney Beach Club Ext Rehab | C42: 1592963.5 | E42: 1566743 | F42: =+IF(E42>0,ROUND((100*C42)/E42,2),0) -> 101.67 | H42: 2383197.3 | J42: =+IF(E42>0,ROUND(H42*F42/100,2),0) -> 2422996.7 | L42: 2383197.3 | N42: =+IF(E42>0,J42-L42,0) -> 39799.4 | P42: =IF(N42<0,IF(-N42<Q42,N42,-Q42),0) -> 0 | Q42: ='August 2026 -AR Aging'!G316 -> 238319.74
A43: 10184 - Project LB Disney* | C43: 1288842.6 | E43: 16424550 | F43: =+IF(E43>0,ROUND((100*C43)/E43,2),0) -> 7.85 | H43: 19323000 | J43: =+IF(E43>0,ROUND(H43*F43/100,2),0) -> 1516855.5 | N43: =+IF(E43>0,J43-L43,0) -> 1516855.5 | P43: =IF(N43<0,IF(-N43<Q43,N43,-Q43),0) -> 0
A44: 10185 - 10185 - FSJ Members Club | C44: 139.52 | E44: 176312 | F44: =+IF(E44>0,ROUND((100*C44)/E44,2),0) -> 0.08 | H44: 187557 | J44: =+IF(E44>0,ROUND(H44*F44/100,2),0) -> 150.05 | N44: =+IF(E44>0,J44-L44,0) -> 150.05 | P44: =IF(N44<0,IF(-N44<Q44,N44,-Q44),0) -> 0
A45: 10186 - Straticon - 4 Seasons Custom* | C45: 210031.39 | E45: 3199314 | F45: =+IF(E45>0,ROUND((100*C45)/E45,2),0) -> 6.56 | H45: 3787250 | J45: =+IF(E45>0,ROUND(H45*F45/100,2),0) -> 248443.6 | L45: 394952.34 | N45: =+IF(E45>0,J45-L45,0) -> -146508.74 | P45: =IF(N45<0,IF(-N45<Q45,N45,-Q45),0) -> -7166.58 | Q45: ='August 2026 -AR Aging'!G324 -> 7166.58
A46: 10187 - 10187 - Ritz Misc Work* | C46: 4453.46 | E46: 15000 | F46: =+IF(E46>0,ROUND((100*C46)/E46,2),0) -> 29.69 | H46: 37384.09 | J46: =+IF(E46>0,ROUND(H46*F46/100,2),0) -> 11099.34 | L46: 37384.09 | N46: =+IF(E46>0,J46-L46,0) -> -26284.75 | P46: =IF(N46<0,IF(-N46<Q46,N46,-Q46),0) -> 0
...

Sheet August 2026 -AR Aging
A6: Accounts Receivable Aging - August 31, 2026
A8: Job | B8: Invoice# | C8: Due Date | E8: Balance | F8: Retained | G8: Current | H8: 1 - 30 | I8: 31 - 60 | J8: 61 - 90 | K8: 91+ | L8: Total Due
A9: 10120 10120 - Waller Creek
B11: 2296 | C11: 10120.01 October | D11: 12/31/2026 | F11: 13398 | G11: 13398 | M11: 0
B12: 2299 | C12: 10120.02 November | D12: 12/31/2026 | F12: 23187.41 | G12: 23187.41 | M12: 0
B13: 2338 | C13: 10120 December | D13: 12/31/2026 | F13: 7895.9 | G13: 7895.9 | M13: 0
B14: 2357 | C14: 10120 January | D14: 12/31/2026 | F14: 62501.6 | G14: 62501.6 | M14: 0
B15: 2412 | C15: 10120 February | D15: 12/31/2026 | F15: 161525.62 | G15: 161525.62 | M15: 0
B16: 2413 | C16: 10120 March | D16: 12/31/2026 | F16: 121182.19 | G16: 121182.19 | M16: 0
B17: 2427 | C17: 10120 April | D17: 12/31/2026 | F17: 177312.62 | G17: 177312.62 | M17: 0
B18: 2445 | C18: 10120 May | D18: 12/31/2026 | F18: 109200.05 | G18: 109200.05 | M18: 0
B19: 2460 | C19: 10120 June | D19: 12/31/2026 | F19: 204970.17 | G19: 204970.17 | M19: 0
B20: 2486 | C20: 10120 July | D20: 12/31/2026 | F20: 147771.55 | G20: 147771.55 | M20: 0
B21: 2510 | C21: 10120 August | D21: 12/31/2026 | F21: 175869.58 | G21: 175869.58 | M21: 0
B22: 2532 | C22: 10120 September | D22: 12/31/2026 | F22: 169230.79 | G22: 169230.79 | M22: 0
... B29: 2735 | C29: 10120 May | D29: 12/31/2026 | F29: 2179.26 | G29: 2179.26 | M29: 0
B30: 2779 | C30: 10120 JULY | D30: 12/31/2026 | F30: 105000 | G30: 10500 | H30: 94500 | M30: 94500
E32: Job Totals: | F32: 1631936.9 | G32: 1537436.9 | H32: 94500 | I32: 0 | J32: 0 | K32: 0 | L32: 0 | M32: 94500
A34: 10123 10123 - 400 Central
B36: 2744 | C36: 10123 June | D36: 06/30/2026 | F36: -6868.32 | G36: 0 | K36: -6868.32 | M36: -6868.32
E38: Job Totals: | F38: -6868.32 | G38: 0 | H38: 0 | I38: 0 | J38: 0 | K38: -6868.32 | L38: 0 | M38: -6868.32
A40: 10128 1000 First Avenue Apartments
B42: 2428 | C42: 10128 April | D42: 01/31/2026 | F42: 13682.61 | G42: 13682.61 | M42: 0
B43: 2443 | C43: 10128 May | D43: 01/31/2026 | F43: 3697.83 | G43: 3697.83 | M43: 0
B44: 2491 | C44: 10128 July | D44: 01/31/2026 | F44: 10060.89 | G44: 10060.89 | M44: 0
B45: 2498 | C45: 10128 August Rev1 | D45: 01/31/2026 | F45: 7312.94 | G45: 7312.94 | M45: 0
B46: 2537 | C46: 10128 September | D46: 01/31/2026 | F46: 2254.06 | G46: 2254.06 | M46: 0
B47: 2551 | C47: 10128 | D47: 01/31/2026 | F47: -19774.76 | G47: 0 | L47: -19774.76 | M47: -19774.76
B48: 2589 | C48: 10128 November | D48: 01/31/2026 | F48: 3270.87 | G48: 3270.87 | M48: 0
B49: 2605 | C49: 10128 Dec | D49: 01/31/2026 | F49: 5135.66 | G49: 5135.65 | L49: 0.01 | M49: 0.01
B50: 2617 | C50: 10128 Dec CO | D50: 01/31/2026 | F50: 1733.83 | G50: 1733.83 | M50: 0
B51: 2618 | C51: 10128 Dec to Bill Ou | D51: 01/30/2026 | F51: 2651.3 | G51: 265.13 | L51: 2386.17 | M51: 2386.17
E53: Job Totals: | F53: 30025.23 | G53: 47413.81 | H53: 0 | I53: 0 | J53: 0 | K53: 0 | L53: -17388.58 | M53: -17388.58
A55: 10130 10130 - Art House Condominiums
B57: 2676 | C57: 10130 | D57: 03/16/2026 | F57: 1627.43 | G57: 1627.43 | M57: 0
E59: Job Totals: | F59: 1627.43 | G59: 1627.43 | H59: 0 | I59: 0 | J59: 0 | K59: 0 | L59: 0 | M59: 0
A61: 10135 10135 - 3rd & 3rd
B63: 2421 | C63: 10135 April | D63: 04/22/2025 | F63: 5900 | G63: 5900 | M63: 0
B64: 2462 | C64: 10135 June | D64: 06/22/2025 | F64: 8955.6 | G64: 8955.6 | M64: 0
B65: 2499 | C65: 10135 July | D65: 08/01/2025 | F65: 28070.9 | G65: 28070.9 | M65: 0
...

Sheet Sheet1
A1: Stowell Prior Year Comparison
C2: 2026 | E2: 2025
C3: August YTD | E3: =C3 -> August YTD | G3: Var
A4: Revenue | C4: ='August 2026 - Inc. Stmt- ALL'!G21 -> 64232711 | E4: ='August 2026 - Inc. Stmt- ALL'!N21 -> 48256343 | G4: =C4-E4 -> 15976368
A6: Direct Expense | C6: ='August 2026 - Inc. Stmt- ALL'!G35 -> 52485705 | E6: ='August 2026 - Inc. Stmt- ALL'!N35 -> 41029273 | G6: =E6-C6 -> -11456432
A8: Gross Profit | C8: ='August 2026 - Inc. Stmt- ALL'!G40 -> 11747006 | E8: ='August 2026 - Inc. Stmt- ALL'!N40 -> 7227069.7 | G8: =C8-E8 -> 4519936.5
A9: Gross Profit % | C9: =C8/C4 -> 0.18288199 | E9: =E8/E4 -> 0.14976414
A11: Total Indirect Expenses | C11: ='August 2026 - Inc. Stmt- ALL'!G98 -> 2085647.1 | E11: ='August 2026 - Inc. Stmt- ALL'!N98 -> 1999035.8 | G11: =E11-C11 -> -86611.39
A12: % of Operating Income | C12: =C11/C4 -> 0.032470172 | E12: =E11/E4 -> 0.041425347
A14: Income from Operations | C14: =C8-C11 -> 9661359 | E14: =E8-E11 -> 5228033.9 | G14: =C14-E14 -> 4433325.1
A15: % of Operating Income | C15: =C14/C4 -> 0.15041182 | E15: =E14/E4 -> 0.10833879
A20: Projected 2026 vs 2025 | C20: Proj 2026 | E20: 2025 Act | G20: Var
A22: Projected Revenue | C22: 94000000 | E22: 78301875 | G22: =C22-E22 -> 15698125
A24: Direct Expense | C24: =C22*0.831 -> 78114000 | E24: 65455966 | G24: =E24-C24 -> -12658034
A26: Gross Profit | C26: =C22-C24 -> 15886000 | E26: =E22-E24 -> 12845910 | G26: =C26-E26 -> 3040090.4
A27: Gross Profit % | C27: =C26/C22 -> 0.169 | E27: =E26/E22 -> 0.16405622
A29: Total Indirect Expenses | C29: ='August 2026 - Inc. Stmt- ALL'!K98 -> 3279206.6 | E29: =8132296.75-4968706.88 -> 3163589.9 | G29: =E29-C29 -> -115616.7
A30: % of Operating Income | C30: =C29/C22 -> 0.034885176 | E30: =E29/E22 -> 0.040402479
A32: Income from Operations | C32: =C26-C29 -> 12606793 | E32: =E26-E29 -> 9682319.7 | G32: =C32-E32 -> 2924473.7
A33: % of Operating Income | C33: =C32/C22 -> 0.13411482 | E33: =E32/E22 -> 0.12365374
A35: Est Bonus Payout | C35: =E35/E26*C26 -> 6144592.3 | E35: 4968706.9 | G35: =E35-C35 -> -1175885.4
A37: Net Income from operations | C37: =C32-C35 -> 6462201.1 | E37: =E32-E35 -> 4713612.9 | G37: =C37-E37 -> 1748588.3
A38: % of Operating Income | C38: =C37/C22 -> 0.06874682 | E38: =E37/E22 -> 0.060197956

Sheet Sheet2
